Workbook

Sheet DASH BOARD
A1: WEEKLY REPORT | G1: MONTHLY SUMMARY | N1: YEARLY SUMMARY
A2: WEEKLY | B2: POS | C2: NEG | D2: TOTAL | E2: YEILD | G2: YEAR | H2: MONTHS | I2: POSITIVE | J2: NEGATIVE | K2: TOTAL | L2: YEILD | N2: YEAR | O2: POS | P2: NEG | Q2: TOTAL | R2: YEILD
A3: 30 | B3: ='AKWAKUMA HTS'!H3 -> 50 | C3: ='AKWAKUMA HTS'!I3 -> 142 | D3: =B3+C3 -> 192 | E3: =B3/D3 -> 0.26041667 | F3: FY 21 | G3: 2020 | H3: OCT | I3: ='AKWAKUMA HTS'!N3 -> 48 | J3: ='AKWAKUMA HTS'!O3 -> 61 | K3: =I3+J3 -> 109 | L3: =I3/K3 -> 0.44036697 | N3: FY 21 | O3: =SUM(I3:I14) -> 3677 | P3: =SUM(J3:J14) -> 12064 | Q3: =O3+P3 -> 15741 | R3: =O3/Q3 -> 0.2335938
A4: 32 | B4: ='AKWAKUMA HTS'!H4 -> 25 | C4: ='AKWAKUMA HTS'!I4 -> 72 | D4: =B4+C4 -> 97 | E4: =B4/D4 -> 0.25773196 | F4: FY 21 | G4: 2020 | H4: NOV | I4: ='AKWAKUMA HTS'!N4 -> 84 | J4: ='AKWAKUMA HTS'!O4 -> 96 | K4: =I4+J4 -> 180 | L4: =I4/K4 -> 0.46666667 | N4: FY 22 | O4: =SUM(I15:I26) -> 186 | P4: =SUM(J15:J26) -> 2039 | Q4: =O4+P4 -> 2225 | R4: =O4/Q4 -> 0.083595506
A5: 33 | B5: ='AKWAKUMA HTS'!H5 -> 122 | C5: ='AKWAKUMA HTS'!I5 -> 1271 | D5: =B5+C5 -> 1393 | E5: =B5/D5 -> 0.087580761 | F5: FY 21 | G5: 2020 | H5: DEC | I5: ='AKWAKUMA HTS'!N5 -> 109 | J5: ='AKWAKUMA HTS'!O5 -> 11 | K5: =I5+J5 -> 120 | L5: =I5/K5 -> 0.90833333
A6: 34 | B6: ='AKWAKUMA HTS'!H6 -> 148 | C6: ='AKWAKUMA HTS'!I6 -> 1653 | D6: =B6+C6 -> 1801 | E6: =B6/D6 -> 0.082176569 | F6: FY 21 | G6: 2021 | H6: JAN | I6: ='AKWAKUMA HTS'!N6 -> 256 | J6: ='AKWAKUMA HTS'!O6 -> 109 | K6: =I6+J6 -> 365 | L6: =I6/K6 -> 0.70136986
A7: 35 | B7: ='AKWAKUMA HTS'!H7+'MBEIRI HTS'!I3 -> 127 | C7: ='AKWAKUMA HTS'!I7+'MBEIRI HTS'!J3 -> 1409 | D7: =B7+C7 -> 1536 | E7: =B7/D7 -> 0.082682292 | F7: FY 21 | G7: 2021 | H7: FEB | I7: ='AKWAKUMA HTS'!N7 -> 418 | J7: ='AKWAKUMA HTS'!O7 -> 956 | K7: =I7+J7 -> 1374 | L7: =I7/K7 -> 0.30422125
A8: 36 | B8: ='AKWAKUMA HTS'!H8 -> 98 | C8: ='AKWAKUMA HTS'!I8 -> 987 | D8: =B8+C8 -> 1085 | E8: =B8/D8 -> 0.090322581 | F8: FY 21 | G8: 2021 | H8: MAR | I8: ='AKWAKUMA HTS'!N8 -> 507 | J8: ='AKWAKUMA HTS'!O8 -> 1577 | K8: =I8+J8 -> 2084 | L8: =I8/K8 -> 0.24328215
A9: 37 | B9: ='AKWAKUMA HTS'!H9 -> 66 | C9: ='AKWAKUMA HTS'!I9 -> 649 | D9: =B9+C9 -> 715 | E9: =B9/D9 -> 0.092307692 | F9: FY 21 | G9: 2021 | H9: APR | I9: ='AKWAKUMA HTS'!N9 -> 454 | J9: ='AKWAKUMA HTS'!O9 -> 55 | K9: =I9+J9 -> 509 | L9: =I9/K9 -> 0.89194499
A10: 38 | B10: ='AKWAKUMA HTS'!H10+'MBEIRI HTS'!I4 -> 177 | C10: ='AKWAKUMA HTS'!I10+'MBEIRI HTS'!J4 -> 1795 | D10: =B10+C10 -> 1972 | E10: =B10/D10 -> 0.089756592 | F10: FY 21 | G10: 2021 | H10: MAY | I10: ='AKWAKUMA HTS'!N10+'MBEIRI HTS'!P3 -> 155 | J10: ='AKWAKUMA HTS'!O10+'MBEIRI HTS'!Q3 -> 50 | K10: =I10+J10 -> 205 | L10: =I10/K10 -> 0.75609756
A11: 1 | B11: ='AKWAKUMA HTS'!H11 -> 35 | C11: ='AKWAKUMA HTS'!I11 -> 400 | D11: =B11+C11 -> 435 | E11: =B11/D11 -> 0.08045977 | F11: FY 21 | G11: 2021 | H11: JUNE | I11: ='AKWAKUMA HTS'!N11+'MBEIRI HTS'!P4 -> 521 | J11: ='AKWAKUMA HTS'!O11+'MBEIRI HTS'!Q4 -> 546 | K11: =I11+J11 -> 1067 | L11: =I11/K11 -> 0.48828491
A12: 2 | B12: ='AKWAKUMA HTS'!H12+'MBEIRI HTS'!I5 -> 151 | C12: ='AKWAKUMA HTS'!I12+'MBEIRI HTS'!J5 -> 1639 | D12: =B12+C12 -> 1790 | E12: =B12/D12 -> 0.084357542 | F12: FY 21 | G12: 2021 | H12: JULY | I12: ='AKWAKUMA HTS'!N12+'MBEIRI HTS'!P5 -> 470 | J12: ='AKWAKUMA HTS'!O12+'MBEIRI HTS'!Q5 -> 2178 | K12: =I12+J12 -> 2648 | L12: =I12/K12 -> 0.17749245
A13: 3 | B13: ='AKWAKUMA HTS'!H13+'MBEIRI HTS'!I6 -> 0 | C13: ='AKWAKUMA HTS'!I13+'MBEIRI HTS'!J6 -> 0 | D13: =B13+C13 -> 0 | E13: =B13/D13 -> #DIV/0! | F13: FY 21 | G13: 2021 | H13: AUG | I13: ='AKWAKUMA HTS'!N13+'MBEIRI HTS'!P6 -> 256 | J13: ='AKWAKUMA HTS'!O13+'MBEIRI HTS'!Q6 -> 2127 | K13: =I13+J13 -> 2383 | L13: =I13/K13 -> 0.10742761
A14: 4 | B14: ='AKWAKUMA HTS'!H14+'MBEIRI HTS'!I7 -> 0 | C14: ='AKWAKUMA HTS'!I14+'MBEIRI HTS'!J7 -> 0 | D14: =B14+C14 -> 0 | E14: =B14/D14 -> #DIV/0! | F14: FY 21 | G14: 2021 | H14: SEP | I14: ='AKWAKUMA HTS'!N14+'MBEIRI HTS'!P7 -> 399 | J14: ='AKWAKUMA HTS'!O14+'MBEIRI HTS'!Q7 -> 4298 | K14: =I14+J14 -> 4697 | L14: =I14/K14 -> 0.084947839
A15: 5 | B15: ='AKWAKUMA HTS'!H15+'MBEIRI HTS'!I8 -> 0 | C15: ='AKWAKUMA HTS'!I15+'MBEIRI HTS'!J8 -> 0 | D15: =B15+C15 -> 0 | E15: =B15/D15 -> #DIV/0! | F15: FY 22 | G15: 2021 | H15: OCT | I15: ='AKWAKUMA HTS'!N15+'MBEIRI HTS'!P8 -> 186 | J15: ='AKWAKUMA HTS'!O15+'MBEIRI HTS'!Q8 -> 2039 | K15: =I15+J15 -> 2225 | L15: =I15/K15 -> 0.083595506
A16: 6 | B16: ='AKWAKUMA HTS'!H16+'MBEIRI HTS'!I9 -> 0 | C16: ='AKWAKUMA HTS'!I16+'MBEIRI HTS'!J9 -> 0 | D16: =B16+C16 -> 0 | E16: =B16/D16 -> #DIV/0! | F16: FY 22 | G16: 2021 | H16: NOV | I16: ='AKWAKUMA HTS'!N16+'MBEIRI HTS'!P9 -> 0 | J16: ='AKWAKUMA HTS'!O16+'MBEIRI HTS'!Q9 -> 0 | K16: =I16+J16 -> 0 | L16: =I16/K16 -> #DIV/0!
A17: 7 | B17: ='AKWAKUMA HTS'!H17+'MBEIRI HTS'!I10 -> 0 | C17: ='AKWAKUMA HTS'!I17+'MBEIRI HTS'!J10 -> 0 | D17: =B17+C17 -> 0 | E17: =B17/D17 -> #DIV/0! | F17: FY 22 | G17: 2021 | H17: DEC | I17: ='AKWAKUMA HTS'!N17+'MBEIRI HTS'!P10 -> 0 | J17: ='AKWAKUMA HTS'!O17+'MBEIRI HTS'!Q10 -> 0 | K17: =I17+J17 -> 0 | L17: =I17/K17 -> #DIV/0!
A18: 8 | B18: ='AKWAKUMA HTS'!H18+'MBEIRI HTS'!I11 -> 0 | C18: ='AKWAKUMA HTS'!I18+'MBEIRI HTS'!J11 -> 0 | D18: =B18+C18 -> 0 | E18: =B18/D18 -> #DIV/0! | F18: FY 22 | G18: 2022 | H18: JAN | I18: ='AKWAKUMA HTS'!N18+'MBEIRI HTS'!P11 -> 0 | J18: ='AKWAKUMA HTS'!O18+'MBEIRI HTS'!Q11 -> 0 | K18: =I18+J18 -> 0 | L18: =I18/K18 -> #DIV/0!
A19: 9 | B19: ='AKWAKUMA HTS'!H19+'MBEIRI HTS'!I12 -> 0 | C19: ='AKWAKUMA HTS'!I19+'MBEIRI HTS'!J12 -> 0 | D19: =B19+C19 -> 0 | E19: =B19/D19 -> #DIV/0! | F19: FY 22 | G19: 2022 | H19: FEB | I19: ='AKWAKUMA HTS'!N19+'MBEIRI HTS'!P12 -> 0 | J19: ='AKWAKUMA HTS'!O19+'MBEIRI HTS'!Q12 -> 0 | K19: =I19+J19 -> 0 | L19: =I19/K19 -> #DIV/0!
A20: 10 | B20: ='AKWAKUMA HTS'!H20+'MBEIRI HTS'!I13 -> 0 | C20: ='AKWAKUMA HTS'!I20+'MBEIRI HTS'!J13 -> 0 | D20: =B20+C20 -> 0 | E20: =B20/D20 -> #DIV/0! | F20: FY 22 | G20: 2022 | H20: MARCH | I20: ='AKWAKUMA HTS'!N20+'MBEIRI HTS'!P13 -> 0 | J20: ='AKWAKUMA HTS'!O20+'MBEIRI HTS'!Q13 -> 0 | K20: =I20+J20 -> 0 | L20: =I20/K20 -> #DIV/0!
A21: 11 | B21: ='AKWAKUMA HTS'!H21+'MBEIRI HTS'!I14 -> 0 | C21: ='AKWAKUMA HTS'!I21+'MBEIRI HTS'!J14 -> 0 | D21: =B21+C21 -> 0 | E21: =B21/D21 -> #DIV/0! | F21: FY 22 | G21: 2022 | H21: APRIL | I21: ='AKWAKUMA HTS'!N21+'MBEIRI HTS'!P14 -> 0 | J21: ='AKWAKUMA HTS'!O21+'MBEIRI HTS'!Q14 -> 0 | K21: =I21+J21 -> 0 | L21: =I21/K21 -> #DIV/0!
A22: 12 | B22: ='AKWAKUMA HTS'!H22+'MBEIRI HTS'!I15 -> 0 | C22: ='AKWAKUMA HTS'!I22+'MBEIRI HTS'!J15 -> 0 | D22: =B22+C22 -> 0 | E22: =B22/D22 -> #DIV/0! | F22: FY 22 | G22: 2022 | H22: MAY | I22: ='AKWAKUMA HTS'!N22+'MBEIRI HTS'!P15 -> 0 | J22: ='AKWAKUMA HTS'!O22+'MBEIRI HTS'!Q15 -> 0 | K22: =I22+J22 -> 0 | L22: =I22/K22 -> #DIV/0!
A23: 13 | B23: ='AKWAKUMA HTS'!H23+'MBEIRI HTS'!I16 -> 0 | C23: ='AKWAKUMA HTS'!I23+'MBEIRI HTS'!J16 -> 0 | D23: =B23+C23 -> 0 | E23: =B23/D23 -> #DIV/0! | H23: JUNE | I23: ='AKWAKUMA HTS'!N23+'MBEIRI HTS'!P16 -> 0 | J23: ='AKWAKUMA HTS'!O23+'MBEIRI HTS'!Q16 -> 0 | K23: =I23+J23 -> 0 | L23: =I23/K23 -> #DIV/0!
A24: 14 | B24: ='AKWAKUMA HTS'!H24+'MBEIRI HTS'!I17 -> 0 | C24: ='AKWAKUMA HTS'!I24+'MBEIRI HTS'!J17 -> 0 | D24: =B24+C24 -> 0 | E24: =B24/D24 -> #DIV/0! | H24: JULY | I24: ='AKWAKUMA HTS'!N24+'MBEIRI HTS'!P17 -> 0 | J24: ='AKWAKUMA HTS'!O24+'MBEIRI HTS'!Q17 -> 0 | K24: =I24+J24 -> 0 | L24: =I24/K24 -> #DIV/0!
A25: 15 | B25: ='AKWAKUMA HTS'!H25+'MBEIRI HTS'!I18 -> 0 | C25: ='AKWAKUMA HTS'!I25+'MBEIRI HTS'!J18 -> 0 | D25: =B25+C25 -> 0 | E25: =B25/D25 -> #DIV/0! | H25: AUG | I25: ='AKWAKUMA HTS'!N25+'MBEIRI HTS'!P18 -> 0 | J25: ='AKWAKUMA HTS'!O25+'MBEIRI HTS'!Q18 -> 0 | K25: =I25+J25 -> 0 | L25: =I25/K25 -> #DIV/0!
A26: 16 | B26: ='AKWAKUMA HTS'!H26+'MBEIRI HTS'!I19 -> 0 | C26: ='AKWAKUMA HTS'!I26+'MBEIRI HTS'!J19 -> 0 | D26: =B26+C26 -> 0 | E26: =B26/D26 -> #DIV/0! | H26: SEPT | I26: ='AKWAKUMA HTS'!N26+'MBEIRI HTS'!P19 -> 0 | J26: ='AKWAKUMA HTS'!O26+'MBEIRI HTS'!Q19 -> 0 | K26: =I26+J26 -> 0 | L26: =I26/K26 -> #DIV/0!
A27: 17 | B27: ='AKWAKUMA HTS'!H27+'MBEIRI HTS'!I20 -> 0 | C27: ='AKWAKUMA HTS'!I27+'MBEIRI HTS'!J20 -> 0 | D27: =B27+C27 -> 0 | E27: =B27/D27 -> #DIV/0! | G27: TOTAL | I27: =SUM(I3:I26) -> 3863 | J27: =SUM(J3:J26) -> 14103 | K27: =SUM(K3:K26) -> 17966 | L27: =I27/K27 -> 0.21501725
A28: 18 | B28: ='AKWAKUMA HTS'!H28+'MBEIRI HTS'!I21 -> 0 | C28: ='AKWAKUMA HTS'!I28+'MBEIRI HTS'!J21 -> 0 | D28: =B28+C28 -> 0 | E28: =B28/D28 -> #DIV/0!
A29: 19 | B29: ='AKWAKUMA HTS'!H29+'MBEIRI HTS'!I22 -> 0 | C29: ='AKWAKUMA HTS'!I29+'MBEIRI HTS'!J22 -> 0 | D29: =B29+C29 -> 0 | E29: =B29/D29 -> #DIV/0!
A30: 20 | B30: ='AKWAKUMA HTS'!H30+'MBEIRI HTS'!I23 -> 0 | C30: ='AKWAKUMA HTS'!I30+'MBEIRI HTS'!J23 -> 0 | D30: =B30+C30 -> 0 | E30: =B30/D30 -> #DIV/0!
A31: 21 | B31: ='AKWAKUMA HTS'!H31+'MBEIRI HTS'!I24 -> 0 | C31: ='AKWAKUMA HTS'!I31+'MBEIRI HTS'!J24 -> 0 | D31: =B31+C31 -> 0 | E31: =B31/D31 -> #DIV/0!
A32: 22 | B32: ='AKWAKUMA HTS'!H32+'MBEIRI HTS'!I25 -> 0 | C32: ='AKWAKUMA HTS'!I32+'MBEIRI HTS'!J25 -> 0 | D32: =B32+C32 -> 0 | E32: =B32/D32 -> #DIV/0!
A33: 23 | B33: ='AKWAKUMA HTS'!H33+'MBEIRI HTS'!I26 -> 0 | C33: ='AKWAKUMA HTS'!I33+'MBEIRI HTS'!J26 -> 0 | D33: =B33+C33 -> 0 | E33: =B33/D33 -> #DIV/0!
A34: 24 | B34: ='AKWAKUMA HTS'!H34+'MBEIRI HTS'!I27 -> 0 | C34: ='AKWAKUMA HTS'!I34+'MBEIRI HTS'!J27 -> 0 | D34: =B34+C34 -> 0 | E34: =B34/D34 -> #DIV/0!
A35: 25 | B35: ='AKWAKUMA HTS'!H35+'MBEIRI HTS'!I28 -> 0 | C35: ='AKWAKUMA HTS'!I35+'MBEIRI HTS'!J28 -> 0 | D35: =B35+C35 -> 0 | E35: =B35/D35 -> #DIV/0!
A36: 26 | B36: ='AKWAKUMA HTS'!H36+'MBEIRI HTS'!I29 -> 0 | C36: ='AKWAKUMA HTS'!I36+'MBEIRI HTS'!J29 -> 0 | D36: =B36+C36 -> 0 | E36: =B36/D36 -> #DIV/0!
A37: 27 | B37: ='AKWAKUMA HTS'!H37+'MBEIRI HTS'!I30 -> 0 | C37: ='AKWAKUMA HTS'!I37+'MBEIRI HTS'!J30 -> 0 | D37: =B37+C37 -> 0 | E37: =B37/D37 -> #DIV/0!
A38: 28 | B38: ='AKWAKUMA HTS'!H38+'MBEIRI HTS'!I31 -> 0 | C38: ='AKWAKUMA HTS'!I38+'MBEIRI HTS'!J31 -> 0 | D38: =B38+C38 -> 0 | E38: =B38/D38 -> #DIV/0!

Sheet GRANULAR ANALYSIS
E22: ,

Sheet AKWAKUMA HTS
A1: S/N | B1: CSN DAILY REPORT | G1: WEEKLY REPORT | L1: CSN MONTHLY REPORT
A2: 1 | B2: DATE | C2: TOTAL TESTED | D2: POSITIVE | E2: NEGATIVE | F2: YIELD | G2: WEEK | H2: pos | I2: neg | J2: total | K2: yield | L2: YEAR | M2: MONTHS | N2: POSITIVE | O2: NEGATIVE | P2: TOTAL TESTED | Q2: YIELD
A3: 2 | B3: 44294 | C3: 95 | D3: 25 | E3: =C3-D3 -> 70 | F3: =D3/C3 -> 0.26315789 | G3: 30 | H3: =SUM(D3:D4) -> 50 | I3: =SUM(E3:E4) -> 142 | J3: =H3+I3 -> 192 | K3: =H3/J3 -> 0.26041667 | L3: 2020 | M3: OCT | N3: 48 | O3: 61 | P3: =N3+O3 -> 109 | Q3: =N3/P3 -> 0.44036697
A4: 3 | B4: 44324 | C4: 97 | D4: 25 | E4: =C4-D4 -> 72 | F4: =D4/C4 -> 0.25773196 | G4: 31 | H4: =SUM(D4:D4) -> 25 | I4: =SUM(E4:E4) -> 72 | J4: =H4+I4 -> 97 | K4: =H4/J4 -> 0.25773196 | L4: 2020 | M4: NOV | N4: 84 | O4: 96 | P4: =N4+O4 -> 180 | Q4: =N4/P4 -> 0.46666667
A5: 4 | B5: 44416 | C5: 38 | D5: 10 | E5: =C5-D5 -> 28 | F5: =D5/C5 -> 0.26315789 | G5: 33 | H5: =SUM(D6:D9) -> 122 | I5: =SUM(E6:E9) -> 1271 | J5: =H5+I5 -> 1393 | K5: =H5/J5 -> 0.087580761 | L5: 2020 | M5: DEC | N5: 109 | O5: 11 | P5: =N5+O5 -> 120 | Q5: =N5/P5 -> 0.90833333
A6: 5 | B6: 24/8/2021 | C6: 369 | D6: 34 | E6: =C6-D6 -> 335 | F6: =D6/C6 -> 0.092140921 | G6: 34 | H6: =SUM(D10:D13) -> 148 | I6: =SUM(E10:E13) -> 1653 | J6: =H6+I6 -> 1801 | K6: =H6/J6 -> 0.082176569 | L6: 2021 | M6: JAN | N6: 256 | O6: 109 | P6: =N6+O6 -> 365 | Q6: =N6/P6 -> 0.70136986
A7: 6 | B7: 25/8/2021 | C7: 252 | D7: 22 | E7: =C7-D7 -> 230 | F7: =D7/C7 -> 0.087301587 | G7: 35 | H7: =SUM(D14:D17) -> 97 | I7: =SUM(E14:E17) -> 1087 | J7: =H7+I7 -> 1184 | K7: =H7/J7 -> 0.081925676 | L7: 2021 | M7: FEB | N7: 418 | O7: 956 | P7: =N7+O7 -> 1374 | Q7: =N7/P7 -> 0.30422125
A8: 7 | B8: 26/8/2021 | C8: 335 | D8: 35 | E8: =C8-D8 -> 300 | F8: =D8/C8 -> 0.10447761 | G8: 36 | H8: =SUM(D18:D20) -> 98 | I8: =SUM(E18:E20) -> 987 | J8: =H8+I8 -> 1085 | K8: =H8/J8 -> 0.090322581 | L8: 2021 | M8: MARCH | N8: 507 | O8: 1577 | P8: =N8+O8 -> 2084 | Q8: =N8/P8 -> 0.24328215
A9: 8 | B9: 27/8/2021 | C9: 437 | D9: 31 | E9: =C9-D9 -> 406 | F9: =D9/C9 -> 0.070938215 | G9: 37 | H9: =SUM(D21:D24) -> 66 | I9: =SUM(E21:E24) -> 649 | J9: =H9+I9 -> 715 | K9: =H9/J9 -> 0.092307692 | L9: 2021 | M9: APRIL | N9: 454 | O9: 55 | P9: =N9+O9 -> 509 | Q9: =N9/P9 -> 0.89194499
A10: 9 | B10: 31/8/2021 | C10: 440 | D10: 40 | E10: =C10-D10 -> 400 | F10: =D10/C10 -> 0.090909091 | G10: 38 | H10: =SUM(D25:D28) -> 127 | I10: =SUM(E25:E28) -> 1295 | J10: =H10+I10 -> 1422 | K10: =H10/J10 -> 0.08931083 | L10: 2021 | M10: MAY | N10: 155 | O10: 50 | P10: =N10+O10 -> 205 | Q10: =N10/P10 -> 0.75609756
A11: 10 | B11: 44205 | C11: 380 | D11: 35 | E11: =C11-D11 -> 345 | F11: =D11/C11 -> 0.092105263 | G11: 1 | H11: =SUM(D29:D29) -> 35 | I11: =SUM(E29:E29) -> 400 | J11: =H11+I11 -> 435 | K11: =H11/J11 -> 0.08045977 | L11: 2021 | M11: JUNE | N11: 355 | O11: 106 | P11: =N11+O11 -> 461 | Q11: =N11/P11 -> 0.77006508
A12: 11 | B12: 44236 | C12: 433 | D12: 33 | E12: =C12-D12 -> 400 | F12: =D12/C12 -> 0.076212471 | G12: 2 | H12: =SUM(D30:D33) -> 101 | I12: =SUM(E30:E33) -> 1136 | J12: =H12+I12 -> 1237 | K12: =H12/J12 -> 0.081649151 | L12: 2021 | M12: JULY | N12: 150 | O12: 1291 | P12: =N12+O12 -> 1441 | Q12: =N12/P12 -> 0.10409438
A13: 12 | B13: 44264 | C13: 548 | D13: 40 | E13: =C13-D13 -> 508 | F13: =D13/C13 -> 0.072992701 | G13: 3 | H13: =SUM(D34:D38) -> 0 | I13: =SUM(E34:E38) -> 0 | J13: =H13+I13 -> 0 | K13: =H13/J13 -> #DIV/0! | L13: 2021 | M13: AUGUST | N13: =SUM(D3:D10) -> 222 | O13: =SUM(E3:E10) -> 1841 | P13: =N13+O13 -> 2063 | Q13: =N13/P13 -> 0.10761028
A14: 13 | B14: 44386 | C14: 232 | D14: 20 | E14: =C14-D14 -> 212 | F14: =D14/C14 -> 0.086206897 | G14: 4 | H14: =SUM(D39:D43) -> 0 | I14: =SUM(E39:E43) -> 0 | J14: =H14+I14 -> 0 | K14: =H14/J14 -> #DIV/0! | L14: 2021 | M14: SEPT | N14: =SUM(D11:D24) -> 369 | O14: =SUM(E11:E24) -> 3976 | P14: =N14+O14 -> 4345 | Q14: =N14/P14 -> 0.084925201
A15: 14 | B15: 44417 | C15: 327 | D15: 27 | E15: =C15-D15 -> 300 | F15: =D15/C15 -> 0.082568807 | G15: 5 | H15: =SUM(D43:D48) -> 0 | I15: =SUM(E43:E48) -> 0 | J15: =H15+I15 -> 0 | K15: =H15/J15 -> #DIV/0! | L15: 2021 | M15: OCT | N15: =SUM(D29:D43) -> 136 | O15: =SUM(E29:E43) -> 1536 | P15: =N15+O15 -> 1672 | Q15: =N15/P15 -> 0.081339713
A16: 15 | B16: 44448 | C16: 352 | D16: 27 | E16: =C16-D16 -> 325 | F16: =D16/C16 -> 0.076704545 | G16: 6 | H16: =SUM(D49:D53) -> 0 | I16: =SUM(E49:E53) -> 0 | J16: =H16+I16 -> 0 | K16: =H16/J16 -> #DIV/0! | L16: 2021 | M16: NOV | N16: =SUM(D44:D65) -> 0 | O16: =SUM(E43:E65) -> 0 | P16: =N16+O16 -> 0 | Q16: =N16/P16 -> #DIV/0!
A17: 16 | B17: 44478 | C17: 273 | D17: 23 | E17: =C17-D17 -> 250 | F17: =D17/C17 -> 0.084249084 | G17: 7 | H17: =SUM(D54:D58) -> 0 | I17: =SUM(E54:E58) -> 0 | J17: =H17+I17 -> 0 | K17: =H17/J17 -> #DIV/0! | L17: 2021 | M17: DEC | N17: =SUM(D66:D77) -> 0 | O17: =SUM(E44:E66) -> 0 | P17: =N17+O17 -> 0 | Q17: =N17/P17 -> #DIV/0!
A18: 17 | B18: 15/9/2021 | C18: 224 | D18: 24 | E18: =C18-D18 -> 200 | F18: =D18/C18 -> 0.10714286 | G18: 8 | H18: =SUM(D59:D63) -> 0 | I18: =SUM(E59:E63) -> 0 | J18: =H18+I18 -> 0 | L18: 2022 | M18: JAN | N18: =SUM(D46:D67) -> 0 | O18: =SUM(E45:E67) -> 0 | P18: =N18+O18 -> 0 | Q18: =N18/P18 -> #DIV/0!
A19: 18 | B19: 16/9/2021 | C19: 451 | D19: 39 | E19: =C19-D19 -> 412 | F19: =D19/C19 -> 0.086474501 | G19: 9 | H19: =SUM(D64:D68) -> 0 | I19: =SUM(E64:E68) -> 0 | J19: =H19+I19 -> 0 | L19: 2022 | M19: FEB | N19: =SUM(D47:D68) -> 0 | O19: =SUM(E46:E68) -> 0 | P19: =N19+O19 -> 0 | Q19: =N19/P19 -> #DIV/0!
A20: 19 | B20: 17/9/2021 | C20: 410 | D20: 35 | E20: =C20-D20 -> 375 | F20: =D20/C20 -> 0.085365854 | G20: 10 | J20: =H20+I20 -> 0 | L20: 2022 | M20: MARCH | N20: =SUM(D48:D69) -> 0 | O20: =SUM(E47:E69) -> 0 | P20: =N20+O20 -> 0 | Q20: =N20/P20 -> #DIV/0!
A21: 20 | B21: 21/9/2021 | C21: 118 | D21: 9 | E21: =C21-D21 -> 109 | F21: =D21/C21 -> 0.076271186 | G21: 11 | J21: =H21+I21 -> 0 | L21: 2022 | M21: APRIL | N21: =SUM(D49:D70) -> 0 | O21: =SUM(E48:E70) -> 0 | P21: =N21+O21 -> 0 | Q21: =N21/P21 -> #DIV/0!
A22: 21 | B22: 22/9/2021 | C22: 282 | D22: 26 | E22: =C22-D22 -> 256 | F22: =D22/C22 -> 0.092198582 | G22: 12 | J22: =H22+I22 -> 0 | L22: 2022 | M22: MAY | N22: =SUM(D50:D71) -> 0 | O22: =SUM(E49:E71) -> 0 | P22: =N22+O22 -> 0 | Q22: =N22/P22 -> #DIV/0!
A23: 22 | B23: 23/9/2021 | C23: 165 | D23: 15 | E23: =C23-D23 -> 150 | F23: =D23/C23 -> 0.090909091 | G23: 13 | L23: 2022 | M23: JUNE | N23: =SUM(D51:D72) -> 0 | O23: =SUM(E50:E72) -> 0 | P23: =N23+O23 -> 0 | Q23: =N23/P23 -> #DIV/0!
A24: 23 | B24: 24/9/2021 | C24: 150 | D24: 16 | E24: =C24-D24 -> 134 | F24: =D24/C24 -> 0.10666667 | G24: 14 | L24: 2022 | M24: JULY | N24: =SUM(D52:D73) -> 0 | O24: =SUM(E51:E73) -> 0 | P24: =N24+O24 -> 0 | Q24: =N24/P24 -> #DIV/0!
A25: 24 | B25: 27/9/2021 | C25: 426 | D25: 36 | E25: =C25-D25 -> 390 | F25: =D25/C25 -> 0.084507042 | G25: 15 | L25: 2022 | M25: AUGUST | N25: =SUM(D53:D74) -> 0 | O25: =SUM(E52:E74) -> 0 | P25: =N25+O25 -> 0 | Q25: =N25/P25 -> #DIV/0!
A26: 25 | B26: 28/9/2021 | C26: 331 | D26: 31 | E26: =C26-D26 -> 300 | F26: =D26/C26 -> 0.093655589 | G26: 16 | L26: 2022 | M26: SEPT | N26: =SUM(D54:D75) -> 0 | O26: =SUM(E53:E75) -> 0 | P26: =N26+O26 -> 0 | Q26: =N26/P26 -> #DIV/0!
A27: 26 | B27: 29/9/2021 | C27: 385 | D27: 35 | E27: =C27-D27 -> 350 | F27: =D27/C27 -> 0.090909091 | G27: 17 | L27: TOTAL | N27: =SUM(N3:N26) -> 3263 | O27: =SUM(O3:O26) -> 11665 | P27: =SUM(P3:P26) -> 14928 | Q27: =N27/P27 -> 0.21858253
A28: 27 | B28: 30/9/2021 | C28: 280 | D28: 25 | E28: =C28-D28 -> 255 | F28: =D28/C28 -> 0.089285714 | G28: 18
A29: 28 | B29: 44326 | C29: 435 | D29: 35 | E29: =C29-D29 -> 400 | F29: =D29/C29 -> 0.08045977 | G29: 19
A30: 29 | B30: 44540 | C30: 603 | D30: 37 | E30: =C30-D30 -> 566 | F30: =D30/C30 -> 0.061359867 | G30: 20
A31: 30 | B31: 13/10/2021 | C31: 279 | D31: 29 | E31: =C31-D31 -> 250 | F31: =D31/C31 -> 0.10394265 | G31: 21
A32: 31 | B32: 14/10/2021 | C32: 240 | D32: 20 | E32: =C32-D32 -> 220 | F32: =D32/C32 -> 0.083333333 | G32: 22
A33: 32 | B33: 15/10/2021 | C33: 115 | D33: 15 | E33: =C33-D33 -> 100 | F33: =D33/C33 -> 0.13043478 | G33: 23
A34: 33 | B34: 18/10/2021 | G34: 24
A35: 34 | B35: 19/10/2021 | G35: 25
A36: 35 | B36: 20/10/2021 | G36: 26
A37: 36 | B37: 21/10/2021 | G37: 27
A38: 37 | B38: 22/10/2021 | G38: 28
A39: 38 | B39: 25/10/2021 | G39: 29
A40: 39 | B40: 26/10/2021 | G40: 30
...

Sheet MBEIRI HTS
A1: S/N | B1: DAILY REPORT | G1: WEEKLY REPORT | M1: MONTHLY REPORT
B2: DATE | C2: TOTAL TESTED | D2: POSITIVE | E2: NEGATIVE | F2: YIELD | G2: S/N | H2: WEEK | I2: POS | J2: NEG | K2: TOTAL | L2: YIELD | M2: FY | N2: YEAR | O2: MONTHS | P2: POSITIVE | Q2: NEGATIVE | R2: TOTAL TESTED | S2: YIELD
A3: 1 | B3: 15/9/2021 | C3: 352 | D3: 30 | E3: =C3-D3 -> 322 | F3: =D3/C3 -> 0.085227273 | G3: 1 | H3: 35 | I3: =SUM(D3:D3) -> 30 | J3: =SUM(E3:E3) -> 322 | K3: =I3+J3 -> 352 | L3: =I3/K3 -> 0.085227273 | M3: FY 21 | N3: 2021 | O3: MAY | R3: =P3+Q3 -> 0 | S3: =P3/R3 -> #DIV/0!
A4: 2 | B4: 30/9/2021 | C4: 550 | D4: 50 | E4: =C4-D4 -> 500 | F4: =D5/C5 -> 0.090909091 | G4: 2 | H4: 38 | I4: =SUM(D4:D4) -> 50 | J4: =SUM(E4:E4) -> 500 | K4: =I4+J4 -> 550 | L4: =I5/K5 -> 0.090415913 | M4: FY 21 | N4: 2021 | O4: JUNE | P4: 166 | Q4: 440 | R4: =P4+Q4 -> 606 | S4: =P4/R4 -> 0.27392739
A5: 3 | B5: 14/10/2021 | C5: 220 | D5: 20 | E5: =C5-D5 -> 200 | F5: =D6/C6 -> 0.09009009 | G5: 3 | H5: 1 | I5: =SUM(D5:D6) -> 50 | J5: =SUM(E5:E7) -> 503 | K5: =I5+J5 -> 553 | L5: =I6/K6 -> #DIV/0! | M5: FY 21 | N5: 2021 | O5: JULY | P5: 320 | Q5: 887 | R5: =P5+Q5 -> 1207 | S5: =P5/R5 -> 0.26512013
A6: 4 | B6: 15/10/2021 | C6: 333 | D6: 30 | E6: =C6-D6 -> 303 | F6: =D7/C7 -> #DIV/0! | G6: 4 | H6: 2 | I6: =SUM(D7:D11) -> 0 | J6: =SUM(E7:E11) -> 0 | K6: =I6+J6 -> 0 | L6: =I7/K7 -> #DIV/0! | M6: FY 21 | N6: 2021 | O6: AUGUST | P6: 34 | Q6: 286 | R6: =P6+Q6 -> 320 | S6: =P6/R6 -> 0.10625
A7: 5 | B7: 18/10/2021 | E7: =C7-D7 -> 0 | F7: =D8/C8 -> #DIV/0! | G7: 5 | H7: 3 | I7: =SUM(D12:D16) -> 0 | J7: =SUM(E12:E16) -> 0 | K7: =I7+J7 -> 0 | L7: =I8/K8 -> #DIV/0! | M7: FY 21 | N7: 2021 | O7: SEPT | P7: =SUM(I3:I3) -> 30 | Q7: =SUM(J3:J3) -> 322 | R7: =P7+Q7 -> 352 | S7: =P7/R7 -> 0.085227273
A8: 6 | B8: 19/10/2021 | E8: =C8-D8 -> 0 | F8: =D9/C9 -> #DIV/0! | G8: 6 | H8: 4 | I8: =SUM(D17:D21) -> 0 | J8: =SUM(E17:E20) -> 0 | K8: =I8+J8 -> 0 | L8: =I9/K9 -> #DIV/0! | M8: FY 22 | N8: 2021 | O8: OCT | P8: =SUM(I5:I16) -> 50 | Q8: =SUM(J5:J16) -> 503 | R8: =P8+Q8 -> 553 | S8: =P8/R8 -> 0.090415913
A9: 7 | B9: 20/10/2021 | E9: =C9-D9 -> 0 | F9: =D10/C10 -> #DIV/0! | G9: 7 | H9: 5 | I9: =SUM(D22:D26) -> 0 | J9: =SUM(E22:E26) -> 0 | K9: =I9+J9 -> 0 | L9: =I10/K10 -> #DIV/0! | M9: FY 22 | N9: 2021 | O9: NOV | P9: =SUM(I17:I38) -> 0 | Q9: =SUM(J17:J38) -> 0 | R9: =P9+Q9 -> 0 | S9: =P9/R9 -> #DIV/0!
A10: 8 | B10: 21/10/2021 | E10: =C10-D10 -> 0 | F10: =D11/C11 -> #DIV/0! | G10: 8 | H10: 6 | I10: =SUM(D27:D31) -> 0 | J10: =SUM(E27:E31) -> 0 | K10: =I10+J10 -> 0 | L10: =I11/K11 -> #DIV/0! | M10: FY 22 | N10: 2021 | O10: DEC | P10: =SUM(I39:I59) -> 0 | Q10: =SUM(J39:J59) -> 0 | R10: =P10+Q10 -> 0 | S10: =P10/R10 -> #DIV/0!
A11: 9 | B11: 22/10/2021 | E11: =C11-D11 -> 0 | F11: =D12/C12 -> #DIV/0! | H11: 7 | I11: =SUM(D32:D36) -> 0 | J11: =SUM(E32:E36) -> 0 | K11: =I11+J11 -> 0 | L11: =I12/K12 -> #DIV/0! | M11: FY 22 | N11: 2022 | O11: JAN | R11: =P11+Q11 -> 0 | S11: =P11/R11 -> #DIV/0!
A12: 10 | B12: 25/10/2021 | E12: =C12-D12 -> 0 | F12: =D13/C13 -> #DIV/0! | H12: 8 | K12: =I12+J12 -> 0 | L12: =I13/K13 -> #DIV/0! | M12: FY 22 | N12: 2022 | O12: FEB | R12: =P12+Q12 -> 0 | S12: =P12/R12 -> #DIV/0!
A13: 11 | B13: 26/10/2021 | E13: =C13-D13 -> 0 | F13: =D14/C14 -> #DIV/0! | H13: 9 | K13: =I13+J13 -> 0 | L13: =I14/K14 -> #DIV/0! | M13: FY 22 | N13: 2022 | O13: MARCH | R13: =P13+Q13 -> 0 | S13: =P13/R13 -> #DIV/0!
A14: 12 | B14: 27/10/2021 | E14: =C14-D14 -> 0 | F14: =D15/C15 -> #DIV/0! | H14: 10 | K14: =I14+J14 -> 0 | L14: =I15/K15 -> #DIV/0! | M14: FY 22 | N14: 2022 | O14: APRIL | R14: =P14+Q14 -> 0 | S14: =P14/R14 -> #DIV/0!
A15: 13 | B15: 28/10/2021 | E15: =C15-D15 -> 0 | F15: =D16/C16 -> #DIV/0! | H15: 11 | K15: =I15+J15 -> 0 | M15: FY 22 | N15: 2022 | O15: MAY | R15: =P15+Q15 -> 0 | S15: =P15/R15 -> #DIV/0!
A16: 14 | B16: 29/10/2021 | E16: =C16-D16 -> 0 | F16: =D17/C17 -> #DIV/0! | H16: 12 | M16: FY 22 | N16: 2022 | O16: JUNE | R16: =P16+Q16 -> 0 | S16: =P16/R16 -> #DIV/0!
A17: 15 | B17: 44207 | E17: =C17-D17 -> 0 | F17: =D18/C18 -> #DIV/0! | H17: 13 | M17: FY 22 | N17: 2022 | O17: JULY | R17: =P17+Q17 -> 0 | S17: =P17/R17 -> #DIV/0!
A18: 16 | B18: 44238 | E18: =C18-D18 -> 0 | F18: =D19/C19 -> #DIV/0! | H18: 14 | M18: FY 22 | N18: 2022 | O18: AUGUST | R18: =P18+Q18 -> 0 | S18: =P18/R18 -> #DIV/0!
A19: 17 | B19: 44266 | E19: =C19-D19 -> 0 | F19: =D20/C20 -> #DIV/0! | H19: 15 | M19: FY 22 | N19: 2022 | O19: SEPT | R19: =P19+Q19 -> 0 | S19: =P19/R19 -> #DIV/0!
A20: 18 | B20: 44297 | E20: =C20-D20 -> 0 | F20: =D21/C21 -> #DIV/0! | H20: 16 | N20: TOTAL | P20: =SUM(P3:P10) -> 600 | Q20: =SUM(Q3:Q10) -> 2438 | R20: =P20+Q20 -> 3038 | S20: =SUM(S3:S10) -> #DIV/0!
A21: 19 | B21: 44327 | E21: =C21-D21 -> 0 | F21: =D22/C22 -> #DIV/0! | H21: 17
A22: 20 | B22: 44419 | E22: =C22-D22 -> 0 | F22: =D23/C23 -> #DIV/0! | H22: 18
A23: 21 | B23: 44450 | E23: =C23-D23 -> 0 | F23: =D24/C24 -> #DIV/0! | H23: 19
A24: 22 | B24: 44480 | E24: =C24-D24 -> 0 | F24: =D25/C25 -> #DIV/0! | H24: 20
A25: 23 | B25: 44511 | E25: =C25-D25 -> 0 | F25: =D26/C26 -> #DIV/0! | H25: 21
A26: 24 | B26: 44541 | E26: =C26-D26 -> 0 | F26: =D27/C27 -> #DIV/0! | H26: 22
A27: 25 | B27: 15/11/2021 | E27: =C27-D27 -> 0 | F27: =D28/C28 -> #DIV/0! | H27: 23
A28: 26 | B28: 16/11/2021 | E28: =C28-D28 -> 0 | F28: =D29/C29 -> #DIV/0! | H28: 24
A29: 27 | B29: 17/11/2021 | E29: =C29-D29 -> 0 | F29: =D30/C30 -> #DIV/0! | H29: 25
A30: 28 | B30: 18/11/2021 | E30: =C30-D30 -> 0 | F30: =D31/C31 -> #DIV/0!
A31: 29 | B31: 19/11/2021 | E31: =C31-D31 -> 0 | F31: =D32/C32 -> #DIV/0!
A32: 30 | B32: 22/11/2021 | E32: =C32-D32 -> 0 | F32: =D33/C33 -> #DIV/0!
A33: 31 | B33: 23/11/2021 | E33: =C33-D33 -> 0 | F33: =D34/C34 -> #DIV/0!
A34: 32 | B34: 24/11/2021 | E34: =C34-D34 -> 0 | F34: =D35/C35 -> #DIV/0!
A35: 33 | B35: 25/11/2021 | E35: =C35-D35 -> 0 | F35: =D36/C36 -> #DIV/0!
A36: 34 | B36: 26/11/2021 | E36: =C36-D36 -> 0 | F36: =D37/C37 -> #DIV/0!
A37: 35 | B37: 29/11/2021 | E37: =C37-D37 -> 0 | F37: =D38/C38 -> #DIV/0!
A38: 36 | B38: 30/11/2021 | E38: =C38-D38 -> 0 | F38: =D39/C39 -> #DIV/0!
A39: 37 | B39: 44208 | E39: =C39-D39 -> 0 | F39: =D40/C40 -> #DIV/0!
A40: 38 | B40: 44239 | E40: =C40-D40 -> 0 | F40: =D41/C41 -> #DIV/0!
...
