Workbook

Sheet DASHBOARD

Sheet APRIL
A1: S/N | B1: VOLUNTEER | C1: Community | D1: SERVICES | F1: Graduated | H1: TARGETS BY HH | J1: TAREGETS MET IN % | L1: NUMBER OF HOUSE HOLD GRADUATED | M1: HH | N1: VC
D2: HH | E2: VC | F2: HH | G2: VC | H2: HH_SERV | I2: HH_GRAD | J2: HH_SERV | K2: HH_GRAD | L2: Lugbe | M2: =SUM(F3) -> 0 | N2: =SUM(G3) -> 0
A3: 1 | B3: Salihu Dimas Gode | C3: Lugbe | D3: 0 | E3: 0 | F3: 0 | G3: 0 | H3: 0 | I3: 0 | J3: =D3/H3 -> #DIV/0! | K3: =M2/I3 -> #DIV/0! | L3: Sauka | M3: =SUM(F4,F22) -> 0 | N3: =SUM(G4,G22) -> 0
A4: 2 | B4: Emmanuel Mluwa Theresa | C4: Sauka | D4: 0 | E4: 0 | F4: 0 | G4: 0 | H4: 0 | I4: 0 | J4: =SUM(D4,D22)/H4 -> #DIV/0! | K4: =M3/I4 -> #DIV/0! | L4: Kabusa | M4: =SUM(F5,F7,F11,F12) -> 0 | N4: =SUM(G5,G7,G11,G12) -> 0
A5: 3 | B5: Kaka Aminu | C5: Kabusa | D5: 0 | E5: 0 | F5: 0 | G5: 0 | H5: 0 | I5: 0 | J5: =SUM(D5,D11,D12,D7)/H5 -> #DIV/0! | K5: =M4/I5 -> #DIV/0! | L5: Jahi | M5: =SUM(F43,F6) -> 0 | N5: =SUM(G6,G43) -> 0
A6: 4 | B6: Yunusa Nura | C6: Jahi | D6: 0 | E6: 0 | F6: 0 | G6: 0 | H6: 0 | I6: 0 | J6: =SUM(D6,D43)/H6 -> #DIV/0! | K6: =M5/I6 -> #DIV/0! | L6: Gishiri | M6: =SUM(F8,F17) -> 0 | N6: =SUM(G8,G17) -> 0
A7: 5 | B7: Joseph Abigail | C7: Kabusa | D7: 0 | E7: 0 | F7: 0 | G7: 0 | H7: 0 | I7: 0 | L7: Sabo-lugbe | M7: =SUM(F9) -> 0 | N7: =SUM(G9) -> 0
A8: 6 | B8: Joseph Moses Bawa | C8: Gishiri | D8: 0 | E8: 0 | F8: 0 | G8: 0 | H8: 0 | I8: 0 | J8: =SUM(D8,D17,D31)/H8 -> #DIV/0! | K8: =M6/I8 -> #DIV/0! | L8: Old Karimo | M8: =SUM(F10,F18,F45,F46) -> 0 | N8: =SUM(G10,G18,G45,G46) -> 0
A9: 7 | B9: Ekeh Jane | C9: Sabo-lugbe | D9: 0 | E9: 0 | F9: 0 | G9: 0 | H9: 0 | I9: 0 | J9: =D9/H9 -> #DIV/0! | K9: =M7/I9 -> #DIV/0! | L9: Angwa-sayawa | M9: =SUM(F13,F14,F15) -> 0 | N9: =SUM(G13,G14,G15) -> 0
A10: 8 | B10: Ajiri Micheal | C10: Old Karimo | D10: 0 | E10: 0 | F10: 0 | G10: 0 | H10: 0 | I10: 0 | J10: =SUM(D10,D18,D25,D45,D46)/H10 -> #DIV/0! | K10: =M8/I10 -> #DIV/0! | L10: Kapwa | M10: =SUM(F16) -> 0 | N10: =SUM(G16) -> 0
A11: 9 | B11: Celina Ojo | C11: Kabusa | D11: 0 | E11: 0 | F11: 0 | G11: 0 | H11: 0 | I11: 0 | L11: Dape | M11: =SUM(F21,F19) -> 0 | N11: =SUM(G21,G19) -> 0
A12: 10 | B12: John Agnes | C12: Kabusa | D12: 0 | E12: 0 | F12: 0 | G12: 0 | H12: 0 | I12: 0 | L12: Tundun wada | M12: =SUM(F20,F29) -> 0 | N12: =SUM(G20,G29) -> 0
A13: 11 | B13: Iliya Arziki | C13: Angwa-sayawa | D13: 0 | E13: 0 | F13: 0 | G13: 0 | H13: 0 | I13: 0 | J13: =SUM(D13,D14,D15)/H13 -> #DIV/0! | K13: =M9/I13 -> #DIV/0! | L13: Kaba | M13: =SUM(F23) -> 0 | N13: =SUM(G23) -> 0
A14: 12 | B14: Zacchaeus Yusuf Peter | C14: Angwa-sayawa | D14: 0 | E14: 0 | F14: 0 | G14: 0 | H14: 0 | I14: 0 | L14: Saburi 2 | M14: =SUM(F24) -> 0 | N14: =SUM(G24) -> 0
A15: 13 | B15: Elijah Obasanjo Sangson | C15: Angwa-sayawa | D15: 0 | E15: 0 | F15: 0 | G15: 0 | H15: 0 | I15: 0 | L15: Deidei | M15: =SUM(F26) -> 0 | N15: =SUM(G26) -> 0
A16: 14 | B16: Yakubu Blessing | C16: Kapwa | D16: 0 | E16: 0 | F16: 0 | G16: 0 | H16: 0 | I16: 0 | J16: =SUM(D16)/H16 -> #DIV/0! | K16: =M10/I16 -> #DIV/0! | L16: Mabuchi | M16: =SUM(F28,F27) -> 0 | N16: =SUM(G27,G28) -> 0
A17: 15 | B17: Fenu Shekwolumi | C17: Gishiri | D17: 0 | E17: 0 | F17: 0 | G17: 0 | H17: 0 | I17: 0 | L17: Saburi 1 | M17: =SUM(F30) -> 0 | N17: =SUM(G30) -> 0
A18: 16 | B18: Ibrahim Hadiza | C18: Old Karimo | D18: 0 | E18: 0 | F18: 0 | G18: 0 | H18: 0 | I18: 0 | L18: Apo Dutse/Wumba | M18: =SUM(F32) -> 0 | N18: =SUM(G32) -> 0
A19: 17 | B19: Sarah Hillary Kiyatti | C19: Dape | D19: 0 | E19: 0 | F19: 0 | G19: 0 | H19: 0 | I19: 0 | J19: =SUM(D19,D21)/H19 -> #DIV/0! | K19: =M11/I19 -> #DIV/0! | L19: Gosa | M19: =SUM(F34,F33) -> 0 | N19: =SUM(G34,G33) -> 0
A20: 18 | B20: Saleh Babale | C20: Tundun wada | D20: 0 | E20: 0 | F20: 0 | G20: 0 | H20: 0 | I20: 0 | J20: =SUM(D20,D29)/H20 -> #DIV/0! | K20: =M12/I20 -> #DIV/0! | L20: Wumba | M20: =SUM(F35) -> 0 | N20: =SUM(G35) -> 0
A21: 19 | B21: Bilikisu Yakubu | C21: Dape | D21: 0 | E21: 0 | F21: 0 | G21: 0 | H21: 0 | I21: 0 | L21: New Karmo | M21: =SUM(F37,F36) -> 0 | N21: =SUM(G37,G36) -> 0
A22: 20 | B22: Solomon P. Kwartong | C22: Sauka | D22: 0 | E22: 0 | F22: 0 | G22: 0 | H22: 0 | I22: 0 | L22: Iddo Pada | M22: =SUM(F38) -> 0 | N22: =SUM(G38) -> 0
A23: 21 | B23: Yakubu Hassaina | C23: Kaba | D23: 0 | E23: 0 | F23: 0 | G23: 0 | H23: 0 | I23: 0 | J23: =SUM(D23)/H23 -> #DIV/0! | K23: =M13/I23 -> #DIV/0! | L23: Waru | M23: =SUM(F40,F39) -> 0 | N23: =SUM(G39,G40) -> 0
A24: 22 | B24: Esther Zaka | C24: Saburi 2 | D24: 0 | E24: 0 | F24: 0 | G24: 0 | H24: 0 | I24: 0 | J24: =SUM(D24)/H24 -> #DIV/0! | K24: =M14/I24 -> #DIV/0! | L24: Kagini | M24: =SUM(F41) -> 0 | N24: =SUM(G41) -> 0
A25: 23 | B25: Aisha Ahmed | C25: Old Karimo | D25: 0 | E25: 0 | F25: 0 | G25: 0 | H25: 0 | I25: 0 | L25: Jiwa | M25: =SUM(F42) -> 0 | N25: =SUM(G42) -> 0
A26: 24 | B26: Faith Kolade Ibigbemi | C26: Deidei | D26: 0 | E26: 0 | F26: 0 | G26: 0 | H26: 0 | I26: 0 | J26: =SUM(D26)/H26 -> #DIV/0! | K26: =M15/I26 -> #DIV/0! | L26: Paipe | M26: =SUM(F44) -> 0 | N26: =SUM(G44) -> 0
A27: 25 | B27: Tanko Dantani | C27: Mabuchi | D27: 0 | E27: 0 | F27: 0 | G27: 0 | H27: 0 | I27: 0 | J27: =SUM(D27:D28)/H27 -> #DIV/0! | K27: =M16/I27 -> #DIV/0! | L27: TOTAL | M27: =SUM(M2:M26) -> 0 | N27: =SUM(N2:N26) -> 0
A28: 26 | B28: Ali Gambo | C28: Mabuchi | D28: 0 | E28: 0 | F28: 0 | G28: 0 | H28: 0 | I28: 0
A29: 27 | B29: Ruth Anna Omijie | C29: Tundun wada | D29: 0 | E29: 0 | F29: 0 | G29: 0 | H29: 0 | I29: 0 | L29: %TARGET MET HH_GRAD | M29: =F48/I48 -> #DIV/0!
A30: 28 | B30: Musa Yahaya | C30: Saburi 1 | D30: 0 | E30: 0 | F30: 0 | G30: 0 | H30: 0 | I30: 0 | J30: =SUM(D30)/H30 -> #DIV/0! | K30: =M17/I31 -> #DIV/0! | L30: %TARGET MET HH_SERV | M30: =D48/H48 -> #DIV/0!
A31: 29 | B31: Sunday Esther | C31: Gishiri | D31: 0 | E31: 0 | F31: 0 | G31: 0 | H31: 0 | I31: 0
A32: 30 | B32: Mariam Idde | C32: Apo Dutse/Wumba | D32: 0 | E32: 0 | F32: 0 | G32: 0 | H32: 0 | I32: 0 | J32: =SUM(D32)/H32 -> #DIV/0! | K32: =M18/I32 -> #DIV/0!
A33: 31 | B33: Baba N. Daniel | C33: Gosa | D33: 0 | E33: 0 | F33: 0 | G33: 0 | H33: 0 | I33: 0 | J33: =SUM(D33:D34)/H33 -> #DIV/0! | K33: =M19/I33 -> #DIV/0!
A34: 32 | B34: Iloh Constance .C | C34: Gosa | D34: 0 | E34: 0 | F34: 0 | G34: 0 | H34: 0 | I34: 0
A35: 33 | B35: Danlami Sunday | C35: Wumba | D35: 0 | E35: 0 | F35: 0 | G35: 0 | H35: 0 | I35: 0 | J35: =SUM(D35)/H35 -> #DIV/0! | K35: =M20/I35 -> #DIV/0!
A36: 34 | B36: Ismaila Rukiya | C36: New Karmo | D36: 0 | E36: 0 | F36: 0 | G36: 0 | H36: 0 | I36: 0 | J36: =SUM(D36:D37)/H36 -> #DIV/0! | K36: =M21/I36 -> #DIV/0!
A37: 35 | B37: Rashida Ohunene Jegede | C37: New Karmo | D37: 0 | E37: 0 | F37: 0 | G37: 0 | H37: 0 | I37: 0
A38: 36 | B38: Patricial Emmanuel | C38: Iddo Pada | D38: 0 | E38: 0 | F38: 0 | G38: 0 | H38: 0 | I38: 0 | J38: =SUM(D38)/H38 -> #DIV/0! | K38: =M22/I38 -> #DIV/0!
A39: 37 | B39: Chinwuba Lilian Chiamaka | C39: Waru | D39: 0 | E39: 0 | F39: 0 | G39: 0 | H39: 0 | I39: 0 | J39: =SUM(D39:D40)/H39 -> #DIV/0! | K39: =M23/I39 -> #DIV/0!
A40: 38 | B40: Akume A. Godwin | C40: Waru | D40: 0 | E40: 0 | F40: 0 | G40: 0 | H40: 0 | I40: 0
...

Sheet MAY
A1: S/N | B1: VOLUNTEER | C1: Community | D1: SERVICES | F1: Graduated | H1: TARGETS BY HH | J1: TAREGETS MET IN % | L1: NUMBER OF HOUSE HOLD GRADUATED | M1: HH | N1: VC
D2: HH | E2: VC | F2: HH | G2: VC | H2: HH_SERV | I2: HH_GRAD | J2: HH_SERV | K2: HH_GRAD | L2: Lugbe | M2: =SUM(F3) -> 0 | N2: =SUM(G3) -> 0
A3: 1 | B3: Salihu Dimas Gode | C3: Lugbe | D3: 0 | E3: 0 | F3: 0 | G3: 0 | H3: 0 | I3: 0 | J3: =D3/H3 -> #DIV/0! | K3: =M2/I3 -> #DIV/0! | L3: Sauka | M3: =SUM(F4,F22) -> 0 | N3: =SUM(G4,G22) -> 0
A4: 2 | B4: Emmanuel Mluwa Theresa | C4: Sauka | D4: 0 | E4: 0 | F4: 0 | G4: 0 | H4: 0 | I4: 0 | J4: =SUM(D4,D22)/H4 -> #DIV/0! | K4: =M3/I4 -> #DIV/0! | L4: Kabusa | M4: =SUM(F5,F7,F11,F12) -> 0 | N4: =SUM(G5,G7,G11,G12) -> 0
A5: 3 | B5: Kaka Aminu | C5: Kabusa | D5: 0 | E5: 0 | F5: 0 | G5: 0 | H5: 0 | I5: 0 | J5: =SUM(D5,D11,D12,D7)/H5 -> #DIV/0! | K5: =M4/I5 -> #DIV/0! | L5: Jahi | M5: =SUM(F43,F6) -> 0 | N5: =SUM(G6,G43) -> 0
A6: 4 | B6: Yunusa Nura | C6: Jahi | D6: 0 | E6: 0 | F6: 0 | G6: 0 | H6: 0 | I6: 0 | J6: =SUM(D6,D43)/H6 -> #DIV/0! | K6: =M5/I6 -> #DIV/0! | L6: Gishiri | M6: =SUM(F8,F17) -> 0 | N6: =SUM(G8,G17) -> 0
A7: 5 | B7: Joseph Abigail | C7: Kabusa | D7: 0 | E7: 0 | F7: 0 | G7: 0 | H7: 0 | I7: 0 | L7: Sabo-lugbe | M7: =SUM(F9) -> 0 | N7: =SUM(G9) -> 0
A8: 6 | B8: Joseph Moses Bawa | C8: Gishiri | D8: 0 | E8: 0 | F8: 0 | G8: 0 | H8: 0 | I8: 0 | J8: =SUM(D8,D17,D31)/H8 -> #DIV/0! | K8: =M6/I8 -> #DIV/0! | L8: Old Karimo | M8: =SUM(F10,F18,F45,F46) -> 0 | N8: =SUM(G10,G18,G45,G46) -> 0
A9: 7 | B9: Ekeh Jane | C9: Sabo-lugbe | D9: 0 | E9: 0 | F9: 0 | G9: 0 | H9: 0 | I9: 0 | J9: =D9/H9 -> #DIV/0! | K9: =M7/I9 -> #DIV/0! | L9: Angwa-sayawa | M9: =SUM(F13,F14,F15) -> 0 | N9: =SUM(G13,G14,G15) -> 0
A10: 8 | B10: Ajiri Micheal | C10: Old Karimo | D10: 0 | E10: 0 | F10: 0 | G10: 0 | H10: 0 | I10: 0 | J10: =SUM(D10,D18,D25,D45,D46)/H10 -> #DIV/0! | K10: =M8/I10 -> #DIV/0! | L10: Kapwa | M10: =SUM(F16) -> 0 | N10: =SUM(G16) -> 0
A11: 9 | B11: Celina Ojo | C11: Kabusa | D11: 0 | E11: 0 | F11: 0 | G11: 0 | H11: 0 | I11: 0 | L11: Dape | M11: =SUM(F21,F19) -> 0 | N11: =SUM(G21,G19) -> 0
A12: 10 | B12: John Agnes | C12: Kabusa | D12: 0 | E12: 0 | F12: 0 | G12: 0 | H12: 0 | I12: 0 | L12: Tundun wada | M12: =SUM(F20,F29) -> 0 | N12: =SUM(G20,G29) -> 0
A13: 11 | B13: Iliya Arziki | C13: Angwa-sayawa | D13: 0 | E13: 0 | F13: 0 | G13: 0 | H13: 0 | I13: 0 | J13: =SUM(D13,D14,D15)/H13 -> #DIV/0! | K13: =M9/I13 -> #DIV/0! | L13: Kaba | M13: =SUM(F23) -> 0 | N13: =SUM(G23) -> 0
A14: 12 | B14: Zacchaeus Yusuf Peter | C14: Angwa-sayawa | D14: 0 | E14: 0 | F14: 0 | G14: 0 | H14: 0 | I14: 0 | L14: Saburi 2 | M14: =SUM(F24) -> 0 | N14: =SUM(G24) -> 0
A15: 13 | B15: Elijah Obasanjo Sangson | C15: Angwa-sayawa | D15: 0 | E15: 0 | F15: 0 | G15: 0 | H15: 0 | I15: 0 | L15: Deidei | M15: =SUM(F26) -> 0 | N15: =SUM(G26) -> 0
A16: 14 | B16: Yakubu Blessing | C16: Kapwa | D16: 0 | E16: 0 | F16: 0 | G16: 0 | H16: 0 | I16: 0 | J16: =SUM(D16)/H16 -> #DIV/0! | K16: =M10/I16 -> #DIV/0! | L16: Mabuchi | M16: =SUM(F28,F27) -> 0 | N16: =SUM(G27,G28) -> 0
A17: 15 | B17: Fenu Shekwolumi | C17: Gishiri | D17: 0 | E17: 0 | F17: 0 | G17: 0 | H17: 0 | I17: 0 | L17: Saburi 1 | M17: =SUM(F30) -> 0 | N17: =SUM(G30) -> 0
A18: 16 | B18: Ibrahim Hadiza | C18: Old Karimo | D18: 0 | E18: 0 | F18: 0 | G18: 0 | H18: 0 | I18: 0 | L18: Apo Dutse/Wumba | M18: =SUM(F32) -> 0 | N18: =SUM(G32) -> 0
A19: 17 | B19: Sarah Hillary Kiyatti | C19: Dape | D19: 0 | E19: 0 | F19: 0 | G19: 0 | H19: 0 | I19: 0 | J19: =SUM(D19,D21)/H19 -> #DIV/0! | K19: =M11/I19 -> #DIV/0! | L19: Gosa | M19: =SUM(F34,F33) -> 0 | N19: =SUM(G34,G33) -> 0
A20: 18 | B20: Saleh Babale | C20: Tundun wada | D20: 0 | E20: 0 | F20: 0 | G20: 0 | H20: 0 | I20: 0 | J20: =SUM(D20,D29)/H20 -> #DIV/0! | K20: =M12/I20 -> #DIV/0! | L20: Wumba | M20: =SUM(F35) -> 0 | N20: =SUM(G35) -> 0
A21: 19 | B21: Bilikisu Yakubu | C21: Dape | D21: 0 | E21: 0 | F21: 0 | G21: 0 | H21: 0 | I21: 0 | L21: New Karmo | M21: =SUM(F37,F36) -> 0 | N21: =SUM(G37,G36) -> 0
A22: 20 | B22: Solomon P. Kwartong | C22: Sauka | D22: 0 | E22: 0 | F22: 0 | G22: 0 | H22: 0 | I22: 0 | L22: Iddo Pada | M22: =SUM(F38) -> 0 | N22: =SUM(G38) -> 0
A23: 21 | B23: Yakubu Hassaina | C23: Kaba | D23: 0 | E23: 0 | F23: 0 | G23: 0 | H23: 0 | I23: 0 | J23: =SUM(D23)/H23 -> #DIV/0! | K23: =M13/I23 -> #DIV/0! | L23: Waru | M23: =SUM(F40,F39) -> 0 | N23: =SUM(G39,G40) -> 0
A24: 22 | B24: Esther Zaka | C24: Saburi 2 | D24: 0 | E24: 0 | F24: 0 | G24: 0 | H24: 0 | I24: 0 | J24: =SUM(D24)/H24 -> #DIV/0! | K24: =M14/I24 -> #DIV/0! | L24: Kagini | M24: =SUM(F41) -> 0 | N24: =SUM(G41) -> 0
A25: 23 | B25: Aisha Ahmed | C25: Old Karimo | D25: 0 | E25: 0 | F25: 0 | G25: 0 | H25: 0 | I25: 0 | L25: Jiwa | M25: =SUM(F42) -> 0 | N25: =SUM(G42) -> 0
A26: 24 | B26: Faith Kolade Ibigbemi | C26: Deidei | D26: 0 | E26: 0 | F26: 0 | G26: 0 | H26: 0 | I26: 0 | J26: =SUM(D26)/H26 -> #DIV/0! | K26: =M15/I26 -> #DIV/0! | L26: Paipe | M26: =SUM(F44) -> 0 | N26: =SUM(G44) -> 0
A27: 25 | B27: Tanko Dantani | C27: Mabuchi | D27: 0 | E27: 0 | F27: 0 | G27: 0 | H27: 0 | I27: 0 | J27: =SUM(D27:D28)/H27 -> #DIV/0! | K27: =M16/I27 -> #DIV/0! | L27: TOTAL | M27: =SUM(M2:M26) -> 0 | N27: =SUM(N2:N26) -> 0
A28: 26 | B28: Ali Gambo | C28: Mabuchi | D28: 0 | E28: 0 | F28: 0 | G28: 0 | H28: 0 | I28: 0
A29: 27 | B29: Ruth Anna Omijie | C29: Tundun wada | D29: 0 | E29: 0 | F29: 0 | G29: 0 | H29: 0 | I29: 0 | L29: %TARGET MET HH_GRAD | M29: =F48/I48 -> #DIV/0!
A30: 28 | B30: Musa Yahaya | C30: Saburi 1 | D30: 0 | E30: 0 | F30: 0 | G30: 0 | H30: 0 | I30: 0 | J30: =SUM(D30)/H30 -> #DIV/0! | K30: =M17/I31 -> #DIV/0! | L30: %TARGET MET HH_SERV | M30: =D48/H48 -> #DIV/0!
A31: 29 | B31: Sunday Esther | C31: Gishiri | D31: 0 | E31: 0 | F31: 0 | G31: 0 | H31: 0 | I31: 0
A32: 30 | B32: Mariam Idde | C32: Apo Dutse/Wumba | D32: 0 | E32: 0 | F32: 0 | G32: 0 | H32: 0 | I32: 0 | J32: =SUM(D32)/H32 -> #DIV/0! | K32: =M18/I32 -> #DIV/0!
A33: 31 | B33: Baba N. Daniel | C33: Gosa | D33: 0 | E33: 0 | F33: 0 | G33: 0 | H33: 0 | I33: 0 | J33: =SUM(D33:D34)/H33 -> #DIV/0! | K33: =M19/I33 -> #DIV/0!
A34: 32 | B34: Iloh Constance .C | C34: Gosa | D34: 0 | E34: 0 | F34: 0 | G34: 0 | H34: 0 | I34: 0
A35: 33 | B35: Danlami Sunday | C35: Wumba | D35: 0 | E35: 0 | F35: 0 | G35: 0 | H35: 0 | I35: 0 | J35: =SUM(D35)/H35 -> #DIV/0! | K35: =M20/I35 -> #DIV/0!
A36: 34 | B36: Ismaila Rukiya | C36: New Karmo | D36: 0 | E36: 0 | F36: 0 | G36: 0 | H36: 0 | I36: 0 | J36: =SUM(D36:D37)/H36 -> #DIV/0! | K36: =M21/I36 -> #DIV/0!
A37: 35 | B37: Rashida Ohunene Jegede | C37: New Karmo | D37: 0 | E37: 0 | F37: 0 | G37: 0 | H37: 0 | I37: 0
A38: 36 | B38: Patricial Emmanuel | C38: Iddo Pada | D38: 0 | E38: 0 | F38: 0 | G38: 0 | H38: 0 | I38: 0 | J38: =SUM(D38)/H38 -> #DIV/0! | K38: =M22/I38 -> #DIV/0!
A39: 37 | B39: Chinwuba Lilian Chiamaka | C39: Waru | D39: 0 | E39: 0 | F39: 0 | G39: 0 | H39: 0 | I39: 0 | J39: =SUM(D39:D40)/H39 -> #DIV/0! | K39: =M23/I39 -> #DIV/0!
A40: 38 | B40: Akume A. Godwin | C40: Waru | D40: 0 | E40: 0 | F40: 0 | G40: 0 | H40: 0 | I40: 0
...

Sheet JUNE
A1: S/N | B1: VOLUNTEER | C1: Community | D1: SERVICES | F1: Graduated | H1: TARGETS BY HH | J1: TAREGETS MET IN % | L1: NUMBER OF HOUSE HOLD GRADUATED | M1: HH | N1: VC
D2: HH | E2: VC | F2: HH | G2: VC | H2: HH_SERV | I2: HH_GRAD | J2: HH_SERV | K2: HH_GRAD | L2: Lugbe | M2: =SUM(F3) -> 0 | N2: =SUM(G3) -> 0
A3: 1 | B3: Salihu Dimas Gode | C3: Lugbe | D3: 0 | E3: 0 | F3: 0 | G3: 0 | H3: 0 | I3: 0 | J3: =D3/H3 -> #DIV/0! | K3: =M2/I3 -> #DIV/0! | L3: Sauka | M3: =SUM(F4,F22) -> 0 | N3: =SUM(G4,G22) -> 0
A4: 2 | B4: Emmanuel Mluwa Theresa | C4: Sauka | D4: 0 | E4: 0 | F4: 0 | G4: 0 | H4: 0 | I4: 0 | J4: =SUM(D4,D22)/H4 -> #DIV/0! | K4: =M3/I4 -> #DIV/0! | L4: Kabusa | M4: =SUM(F5,F7,F11,F12) -> 0 | N4: =SUM(G5,G7,G11,G12) -> 0
A5: 3 | B5: Kaka Aminu | C5: Kabusa | D5: 0 | E5: 0 | F5: 0 | G5: 0 | H5: 0 | I5: 0 | J5: =SUM(D5,D11,D12,D7)/H5 -> #DIV/0! | K5: =M4/I5 -> #DIV/0! | L5: Jahi | M5: =SUM(F43,F6) -> 0 | N5: =SUM(G6,G43) -> 0
A6: 4 | B6: Yunusa Nura | C6: Jahi | D6: 0 | E6: 0 | F6: 0 | G6: 0 | H6: 0 | I6: 0 | J6: =SUM(D6,D43)/H6 -> #DIV/0! | K6: =M5/I6 -> #DIV/0! | L6: Gishiri | M6: =SUM(F8,F17) -> 0 | N6: =SUM(G8,G17) -> 0
A7: 5 | B7: Joseph Abigail | C7: Kabusa | D7: 0 | E7: 0 | F7: 0 | G7: 0 | H7: 0 | I7: 0 | L7: Sabo-lugbe | M7: =SUM(F9) -> 0 | N7: =SUM(G9) -> 0
A8: 6 | B8: Joseph Moses Bawa | C8: Gishiri | D8: 0 | E8: 0 | F8: 0 | G8: 0 | H8: 0 | I8: 0 | J8: =SUM(D8,D17,D31)/H8 -> #DIV/0! | K8: =M6/I8 -> #DIV/0! | L8: Old Karimo | M8: =SUM(F10,F18,F45,F46) -> 0 | N8: =SUM(G10,G18,G45,G46) -> 0
A9: 7 | B9: Ekeh Jane | C9: Sabo-lugbe | D9: 0 | E9: 0 | F9: 0 | G9: 0 | H9: 0 | I9: 0 | J9: =D9/H9 -> #DIV/0! | K9: =M7/I9 -> #DIV/0! | L9: Angwa-sayawa | M9: =SUM(F13,F14,F15) -> 0 | N9: =SUM(G13,G14,G15) -> 0
A10: 8 | B10: Ajiri Micheal | C10: Old Karimo | D10: 0 | E10: 0 | F10: 0 | G10: 0 | H10: 0 | I10: 0 | J10: =SUM(D10,D18,D25,D45,D46)/H10 -> #DIV/0! | K10: =M8/I10 -> #DIV/0! | L10: Kapwa | M10: =SUM(F16) -> 0 | N10: =SUM(G16) -> 0
A11: 9 | B11: Celina Ojo | C11: Kabusa | D11: 0 | E11: 0 | F11: 0 | G11: 0 | H11: 0 | I11: 0 | L11: Dape | M11: =SUM(F21,F19) -> 0 | N11: =SUM(G21,G19) -> 0
A12: 10 | B12: John Agnes | C12: Kabusa | D12: 0 | E12: 0 | F12: 0 | G12: 0 | H12: 0 | I12: 0 | L12: Tundun wada | M12: =SUM(F20,F29) -> 0 | N12: =SUM(G20,G29) -> 0
A13: 11 | B13: Iliya Arziki | C13: Angwa-sayawa | D13: 0 | E13: 0 | F13: 0 | G13: 0 | H13: 0 | I13: 0 | J13: =SUM(D13,D14,D15)/H13 -> #DIV/0! | K13: =M9/I13 -> #DIV/0! | L13: Kaba | M13: =SUM(F23) -> 0 | N13: =SUM(G23) -> 0
A14: 12 | B14: Zacchaeus Yusuf Peter | C14: Angwa-sayawa | D14: 0 | E14: 0 | F14: 0 | G14: 0 | H14: 0 | I14: 0 | L14: Saburi 2 | M14: =SUM(F24) -> 0 | N14: =SUM(G24) -> 0
A15: 13 | B15: Elijah Obasanjo Sangson | C15: Angwa-sayawa | D15: 0 | E15: 0 | F15: 0 | G15: 0 | H15: 0 | I15: 0 | L15: Deidei | M15: =SUM(F26) -> 0 | N15: =SUM(G26) -> 0
A16: 14 | B16: Yakubu Blessing | C16: Kapwa | D16: 0 | E16: 0 | F16: 0 | G16: 0 | H16: 0 | I16: 0 | J16: =SUM(D16)/H16 -> #DIV/0! | K16: =M10/I16 -> #DIV/0! | L16: Mabuchi | M16: =SUM(F28,F27) -> 0 | N16: =SUM(G27,G28) -> 0
A17: 15 | B17: Fenu Shekwolumi | C17: Gishiri | D17: 0 | E17: 0 | F17: 0 | G17: 0 | H17: 0 | I17: 0 | L17: Saburi 1 | M17: =SUM(F30) -> 0 | N17: =SUM(G30) -> 0
A18: 16 | B18: Ibrahim Hadiza | C18: Old Karimo | D18: 0 | E18: 0 | F18: 0 | G18: 0 | H18: 0 | I18: 0 | L18: Apo Dutse/Wumba | M18: =SUM(F32) -> 0 | N18: =SUM(G32) -> 0
A19: 17 | B19: Sarah Hillary Kiyatti | C19: Dape | D19: 0 | E19: 0 | F19: 0 | G19: 0 | H19: 0 | I19: 0 | J19: =SUM(D19,D21)/H19 -> #DIV/0! | K19: =M11/I19 -> #DIV/0! | L19: Gosa | M19: =SUM(F34,F33) -> 0 | N19: =SUM(G34,G33) -> 0
A20: 18 | B20: Saleh Babale | C20: Tundun wada | D20: 0 | E20: 0 | F20: 0 | G20: 0 | H20: 0 | I20: 0 | J20: =SUM(D20,D29)/H20 -> #DIV/0! | K20: =M12/I20 -> #DIV/0! | L20: Wumba | M20: =SUM(F35) -> 0 | N20: =SUM(G35) -> 0
A21: 19 | B21: Bilikisu Yakubu | C21: Dape | D21: 0 | E21: 0 | F21: 0 | G21: 0 | H21: 0 | I21: 0 | L21: New Karmo | M21: =SUM(F37,F36) -> 0 | N21: =SUM(G37,G36) -> 0
A22: 20 | B22: Solomon P. Kwartong | C22: Sauka | D22: 0 | E22: 0 | F22: 0 | G22: 0 | H22: 0 | I22: 0 | L22: Iddo Pada | M22: =SUM(F38) -> 0 | N22: =SUM(G38) -> 0
A23: 21 | B23: Yakubu Hassaina | C23: Kaba | D23: 0 | E23: 0 | F23: 0 | G23: 0 | H23: 0 | I23: 0 | J23: =SUM(D23)/H23 -> #DIV/0! | K23: =M13/I23 -> #DIV/0! | L23: Waru | M23: =SUM(F40,F39) -> 0 | N23: =SUM(G39,G40) -> 0
A24: 22 | B24: Esther Zaka | C24: Saburi 2 | D24: 0 | E24: 0 | F24: 0 | G24: 0 | H24: 0 | I24: 0 | J24: =SUM(D24)/H24 -> #DIV/0! | K24: =M14/I24 -> #DIV/0! | L24: Kagini | M24: =SUM(F41) -> 0 | N24: =SUM(G41) -> 0
A25: 23 | B25: Aisha Ahmed | C25: Old Karimo | D25: 0 | E25: 0 | F25: 0 | G25: 0 | H25: 0 | I25: 0 | L25: Jiwa | M25: =SUM(F42) -> 0 | N25: =SUM(G42) -> 0
A26: 24 | B26: Faith Kolade Ibigbemi | C26: Deidei | D26: 0 | E26: 0 | F26: 0 | G26: 0 | H26: 0 | I26: 0 | J26: =SUM(D26)/H26 -> #DIV/0! | K26: =M15/I26 -> #DIV/0! | L26: Paipe | M26: =SUM(F44) -> 0 | N26: =SUM(G44) -> 0
A27: 25 | B27: Tanko Dantani | C27: Mabuchi | D27: 0 | E27: 0 | F27: 0 | G27: 0 | H27: 0 | I27: 0 | J27: =SUM(D27:D28)/H27 -> #DIV/0! | K27: =M16/I27 -> #DIV/0! | L27: TOTAL | M27: =SUM(M2:M26) -> 0 | N27: =SUM(N2:N26) -> 0
A28: 26 | B28: Ali Gambo | C28: Mabuchi | D28: 0 | E28: 0 | F28: 0 | G28: 0 | H28: 0 | I28: 0
A29: 27 | B29: Ruth Anna Omijie | C29: Tundun wada | D29: 0 | E29: 0 | F29: 0 | G29: 0 | H29: 0 | I29: 0 | L29: %TARGET MET HH_GRAD | M29: =F48/I48 -> #DIV/0!
A30: 28 | B30: Musa Yahaya | C30: Saburi 1 | D30: 0 | E30: 0 | F30: 0 | G30: 0 | H30: 0 | I30: 0 | J30: =SUM(D30)/H30 -> #DIV/0! | K30: =M17/I31 -> #DIV/0! | L30: %TARGET MET HH_SERV | M30: =D48/H48 -> #DIV/0!
A31: 29 | B31: Sunday Esther | C31: Gishiri | D31: 0 | E31: 0 | F31: 0 | G31: 0 | H31: 0 | I31: 0
A32: 30 | B32: Mariam Idde | C32: Apo Dutse/Wumba | D32: 0 | E32: 0 | F32: 0 | G32: 0 | H32: 0 | I32: 0 | J32: =SUM(D32)/H32 -> #DIV/0! | K32: =M18/I32 -> #DIV/0!
A33: 31 | B33: Baba N. Daniel | C33: Gosa | D33: 0 | E33: 0 | F33: 0 | G33: 0 | H33: 0 | I33: 0 | J33: =SUM(D33:D34)/H33 -> #DIV/0! | K33: =M19/I33 -> #DIV/0!
A34: 32 | B34: Iloh Constance .C | C34: Gosa | D34: 0 | E34: 0 | F34: 0 | G34: 0 | H34: 0 | I34: 0
A35: 33 | B35: Danlami Sunday | C35: Wumba | D35: 0 | E35: 0 | F35: 0 | G35: 0 | H35: 0 | I35: 0 | J35: =SUM(D35)/H35 -> #DIV/0! | K35: =M20/I35 -> #DIV/0!
A36: 34 | B36: Ismaila Rukiya | C36: New Karmo | D36: 0 | E36: 0 | F36: 0 | G36: 0 | H36: 0 | I36: 0 | J36: =SUM(D36:D37)/H36 -> #DIV/0! | K36: =M21/I36 -> #DIV/0!
A37: 35 | B37: Rashida Ohunene Jegede | C37: New Karmo | D37: 0 | E37: 0 | F37: 0 | G37: 0 | H37: 0 | I37: 0
A38: 36 | B38: Patricial Emmanuel | C38: Iddo Pada | D38: 0 | E38: 0 | F38: 0 | G38: 0 | H38: 0 | I38: 0 | J38: =SUM(D38)/H38 -> #DIV/0! | K38: =M22/I38 -> #DIV/0!
A39: 37 | B39: Chinwuba Lilian Chiamaka | C39: Waru | D39: 0 | E39: 0 | F39: 0 | G39: 0 | H39: 0 | I39: 0 | J39: =SUM(D39:D40)/H39 -> #DIV/0! | K39: =M23/I39 -> #DIV/0!
A40: 38 | B40: Akume A. Godwin | C40: Waru | D40: 0 | E40: 0 | F40: 0 | G40: 0 | H40: 0 | I40: 0
...

Sheet Q3
A1: HOUSE HOLD GRADUATED FROM APRIL-JUNE 2020 | B1: TOTAL | E1: HH_GRAD TOTAL | J1: HOUSE HOLD SERVED FROM APRIL-JUNE 2020 | K1: TOTAL
A2: Lugbe | B2: =APRIL!$M$2+MAY!M2+JUNE!M2 -> 0 | E2: MONTH | F2: TOTAL | G2: Column1 | J2: Lugbe | K2: =APRIL!$D$3+MAY!D3+JUNE!D3 -> 0
A3: Sauka | B3: =APRIL!$M$3+MAY!M3+JUNE!M3 -> 0 | E3: APRIL | F3: =APRIL!$M$27/F7 -> #DIV/0! | G3: =1-Table1[[#This Row],[TOTAL]] -> #DIV/0! | J3: Sauka | K3: =APRIL!$D$22+APRIL!D4+MAY!D4+MAY!D22+JUNE!D4+JUNE!D22 -> 0
A4: Kabusa | B4: =APRIL!$M$4+MAY!M4+JUNE!M4 -> 0 | E4: MAY | F4: =MAY!$M$27/F7 -> #DIV/0! | G4: =1-Table1[[#This Row],[TOTAL]] -> #DIV/0! | J4: Kabusa | K4: =APRIL!$D$5+APRIL!D7+APRIL!D11+APRIL!D12+MAY!D7+MAY!D11+MAY!D5+MAY!D12+JUNE!D5+JUNE!D7+JUNE!D11+JUNE!D12 -> 0
A5: Jahi | B5: =APRIL!$M$5+MAY!M5+JUNE!M5 -> 0 | E5: JUNE | F5: =JUNE!$M$27/F7 -> #DIV/0! | G5: =1-Table1[[#This Row],[TOTAL]] -> #DIV/0! | J5: Jahi | K5: =APRIL!$D$6+APRIL!D43+MAY!D6+MAY!D43+JUNE!D6+JUNE!D43 -> 0
A6: Gishiri | B6: =APRIL!$M$6+MAY!M6+JUNE!M6 -> 0 | E6: TOTAL | F6: =SUM(F3,F4,F5) -> #DIV/0! | J6: Gishiri | K6: =APRIL!$D$8+APRIL!D31+MAY!D8+MAY!D31+JUNE!D8+JUNE!D31 -> 0
A7: Sabo-lugbe | B7: =APRIL!$M$7+MAY!M7+JUNE!M7 -> 0 | E7: TARGET TOTAL | F7: =APRIL!I47+MAY!I47+JUNE!I47 -> 0 | J7: Sabo-lugbe | K7: =APRIL!$D$9+MAY!D9+JUNE!D9 -> 0
A8: Old Karimo | B8: =APRIL!$M$8+MAY!M8+JUNE!M8 -> 0 | J8: Old Karimo | K8: =APRIL!$D$10+APRIL!D18+APRIL!D25+APRIL!D45+APRIL!D46+MAY!D10+MAY!D18+MAY!D25+MAY!D45+MAY!D46+JUNE!D10+JUNE!D18+JUNE!D25+JUNE!D45+JUNE!D46 -> 0
A9: Angwa-sayawa | B9: =APRIL!$M$9+MAY!M9+JUNE!M9 -> 0 | E9: HH_SERVED TOTAL | J9: Angwa-sayawa | K9: =APRIL!$D$13+APRIL!D14+APRIL!D15+MAY!D13+MAY!D14+MAY!D15+JUNE!D13+JUNE!D14+JUNE!D15 -> 0
A10: Kapwa | B10: =APRIL!$M$10+MAY!M10+JUNE!M10 -> 0 | E10: MONTH | F10: TOTAL | J10: Kapwa | K10: =APRIL!$D$16+MAY!D16+JUNE!D16 -> 0
A11: Dape | B11: =APRIL!$M$11+MAY!M11+JUNE!M11 -> 0 | E11: APRIL | F11: =APRIL!$D$47/F15 -> #DIV/0! | G11: =1-F11 -> #DIV/0! | J11: Dape | K11: =APRIL!$D$19+APRIL!D21+MAY!D19+MAY!D21+JUNE!D19+JUNE!D21 -> 0
A12: Tundun wada | B12: =APRIL!$M$12+MAY!M12+JUNE!M12 -> 0 | E12: MAY | F12: =MAY!$D$47/F15 -> #DIV/0! | G12: =1-F12 -> #DIV/0! | J12: Tundun wada | K12: =APRIL!$D$20+APRIL!D29+MAY!D20+MAY!D29+JUNE!D20+JUNE!D29 -> 0
A13: Kaba | B13: =APRIL!$M$13+MAY!M13+JUNE!M13 -> 0 | E13: JUNE | F13: =JUNE!$D$47/F15 -> #DIV/0! | G13: =1-F13 -> #DIV/0! | J13: Kaba | K13: =APRIL!$D$23+MAY!D23+JUNE!D23 -> 0
A14: Saburi 2 | B14: =APRIL!$M$14+MAY!M14+JUNE!M14 -> 0 | E14: TOTAL | F14: =SUM(F11:F13) -> #DIV/0! | J14: Saburi 2 | K14: =APRIL!$D$24+MAY!D24+JUNE!D24 -> 0
A15: Deidei | B15: =APRIL!$M$15+MAY!M15+JUNE!M15 -> 0 | E15: TARGET TOTAL | F15: =APRIL!H47+MAY!H47+JUNE!H47 -> 0 | J15: Deidei | K15: =APRIL!$D$26+MAY!D26+JUNE!D26 -> 0
A16: Mabuchi | B16: =APRIL!$M$16+MAY!M16+JUNE!M16 -> 0 | J16: Mabuchi | K16: =APRIL!$D$27+APRIL!D28+MAY!D27+MAY!D28+JUNE!D27+JUNE!D28 -> 0
A17: Saburi 1 | B17: =APRIL!$M$17+MAY!M17+JUNE!M17 -> 0 | J17: Saburi 1 | K17: =APRIL!$D$30+MAY!D30+JUNE!D30 -> 0
A18: Apo Dutse/Wumba | B18: =APRIL!$M$18+MAY!M18+JUNE!M18 -> 0 | J18: Apo Dutse/Wumba | K18: =APRIL!$D$32+MAY!D32+JUNE!D32 -> 0
A19: Gosa | B19: =APRIL!$M$19+MAY!M19+JUNE!M19 -> 0 | J19: Gosa | K19: =APRIL!$D$33+APRIL!D34+MAY!D33+MAY!D34+JUNE!D33+JUNE!D34 -> 0
A20: Wumba | B20: =APRIL!$M$20+MAY!M20+JUNE!M20 -> 0 | J20: Wumba | K20: =APRIL!$D$35+MAY!D35+JUNE!D35 -> 0
A21: New Karmo | B21: =APRIL!$M$21+MAY!M21+JUNE!M21 -> 0 | J21: New Karmo | K21: =APRIL!$D$36+APRIL!D37+MAY!D36+MAY!D37+JUNE!D36+JUNE!D37 -> 0
A22: Iddo Pada | B22: =APRIL!$M$22+MAY!M22+JUNE!M22 -> 0 | J22: Iddo Pada | K22: =APRIL!$D$38+MAY!D38+JUNE!D38 -> 0
A23: Waru | B23: =APRIL!$M$23+MAY!M23+JUNE!M23 -> 0 | J23: Waru | K23: =APRIL!$D$39+APRIL!D40+MAY!D39+MAY!D40+JUNE!D39+JUNE!D40 -> 0
A24: Kagini | B24: =APRIL!$M$24+MAY!M24+JUNE!M24 -> 0 | J24: Kagini | K24: =APRIL!$D$41+MAY!D41+JUNE!D41 -> 0
A25: Jiwa | B25: =APRIL!$M$25+MAY!M25+JUNE!M25 -> 0 | J25: Jiwa | K25: =APRIL!$D$42+MAY!D42+JUNE!D42 -> 0
A26: Paipe | B26: =APRIL!$M$26+MAY!M26+JUNE!M26 -> 0 | J26: Paipe | K26: =APRIL!$D$44+MAY!D44+JUNE!D44 -> 0
A27: TOTAL | B27: =SUM(B2:B26) -> 0 | J27: TOTAL MET | K27: =SUM(K2:K26) -> 0
J28: TARGET TOTAL | K28: =APRIL!$H$47+MAY!H47+JUNE!H47 -> 0
